<?xml version="1.0"?>
<robot xmlns:xacro="http://www.ros.org/wiki/xacro">
     
    <!-- Макрос -->
    <xacro:macro name="wheel_link" params="prefix">
        <link name="${prefix}_wheel_link">
            <visual>
                <geometry>
                    <cylinder radius="${wheel_radius}" length="${wheel_length}" />
                </geometry>
                <origin xyz="0 0 0" rpy="${pi / 2.0} 0 0" />
                <material name="grey" />
            </visual>
            <collision>
                <geometry>
                    <cylinder radius="${wheel_radius}" length="${wheel_length}" />
                </geometry>
                <origin xyz="0 0 0" rpy="${pi / 2.0} 0 0" />
            </collision>
            <xacro:cylinder_inertial mass="${wheel_mass}" radius="${wheel_radius}" length="${wheel_length}"/>
        </link>
    </xacro:macro>

    <!-- Ссылки -->
    <xacro:wheel_link prefix="front_left" />
    <xacro:wheel_link prefix="front_right" />
    <xacro:wheel_link prefix="rear_left" />
    <xacro:wheel_link prefix="rear_right" />

    <!-- Соединения -->
    <joint name="base_front_left_wheel_joint" type="continuous">
        <parent link="base_link" />
        <child link="front_left_wheel_link" />
        <origin xyz="${wheel_separation_x / 2} ${wheel_separation_y / 2} 0" />
        <axis xyz="0 1 0" />
    </joint>

    <joint name="base_front_right_wheel_joint" type="continuous">
        <parent link="base_link" />
        <child link="front_right_wheel_link" />
        <origin xyz="${wheel_separation_x / 2} ${ - wheel_separation_y / 2} 0" />
        <axis xyz="0 1 0" />
    </joint>

    <joint name="base_rear_left_wheel_joint" type="continuous">
        <parent link="base_link" />
        <child link="rear_left_wheel_link" />
        <origin xyz="${ - wheel_separation_x / 2} ${wheel_separation_y / 2} 0" />
        <axis xyz="0 1 0" />
    </joint>

    <joint name="base_rear_right_wheel_joint" type="continuous">
        <parent link="base_link" />
        <child link="rear_right_wheel_link" />
        <origin xyz="${ - wheel_separation_x / 2} ${ - wheel_separation_y / 2} 0" />
        <axis xyz="0 1 0" />
    </joint> 

</robot>
